{
 "cells": [
  {
   "cell_type": "markdown",
   "id": "b5ed7bef-3b54-4761-84ba-7f01c72f4567",
   "metadata": {},
   "source": [
    "# Transfer Learning\n",
    "\n",
    "* Can Leverage an existing Neural Network architecture which has already learned patterns on similar data to our own\n",
    "\n",
    "* Tune it according to your own problem"
   ]
  },
  {
   "cell_type": "markdown",
   "id": "7e8486af-8afa-4e6b-a9ef-22387813540c",
   "metadata": {},
   "source": [
    "## Part 1: Feature Extraction"
   ]
  },
  {
   "cell_type": "markdown",
   "id": "1552ee3e-be07-4d7c-a8bd-dc9b81a524e6",
   "metadata": {},
   "source": [
    "#### Becoming One with Data"
   ]
  },
  {
   "cell_type": "code",
   "execution_count": 1,
   "id": "4f831f2e-030c-49c1-8445-c16647ae5beb",
   "metadata": {},
   "outputs": [
    {
     "name": "stdout",
     "output_type": "stream",
     "text": [
      "There are 2 directories, 0 images in 10_food_classes_10_percent\n",
      "There are 10 directories, 0 images in 10_food_classes_10_percent\\test\n",
      "There are 0 directories, 250 images in 10_food_classes_10_percent\\test\\chicken_curry\n",
      "There are 0 directories, 250 images in 10_food_classes_10_percent\\test\\chicken_wings\n",
      "There are 0 directories, 250 images in 10_food_classes_10_percent\\test\\fried_rice\n",
      "There are 0 directories, 250 images in 10_food_classes_10_percent\\test\\grilled_salmon\n",
      "There are 0 directories, 250 images in 10_food_classes_10_percent\\test\\hamburger\n",
      "There are 0 directories, 250 images in 10_food_classes_10_percent\\test\\ice_cream\n",
      "There are 0 directories, 250 images in 10_food_classes_10_percent\\test\\pizza\n",
      "There are 0 directories, 250 images in 10_food_classes_10_percent\\test\\ramen\n",
      "There are 0 directories, 250 images in 10_food_classes_10_percent\\test\\steak\n",
      "There are 0 directories, 250 images in 10_food_classes_10_percent\\test\\sushi\n",
      "There are 10 directories, 0 images in 10_food_classes_10_percent\\train\n",
      "There are 0 directories, 75 images in 10_food_classes_10_percent\\train\\chicken_curry\n",
      "There are 0 directories, 75 images in 10_food_classes_10_percent\\train\\chicken_wings\n",
      "There are 0 directories, 75 images in 10_food_classes_10_percent\\train\\fried_rice\n",
      "There are 0 directories, 75 images in 10_food_classes_10_percent\\train\\grilled_salmon\n",
      "There are 0 directories, 75 images in 10_food_classes_10_percent\\train\\hamburger\n",
      "There are 0 directories, 75 images in 10_food_classes_10_percent\\train\\ice_cream\n",
      "There are 0 directories, 75 images in 10_food_classes_10_percent\\train\\pizza\n",
      "There are 0 directories, 75 images in 10_food_classes_10_percent\\train\\ramen\n",
      "There are 0 directories, 75 images in 10_food_classes_10_percent\\train\\steak\n",
      "There are 0 directories, 75 images in 10_food_classes_10_percent\\train\\sushi\n"
     ]
    }
   ],
   "source": [
    "# How many images in each folder?\n",
    "import os\n",
    "\n",
    "# Walk through 10% data directory & list no. of files\n",
    "for dirpath,dirnames,filenames in os.walk('10_food_classes_10_percent'):\n",
    "    print(f\"There are {len(dirnames)} directories, {len(filenames)} images in {dirpath}\")\n"
   ]
  },
  {
   "cell_type": "markdown",
   "id": "9531f373-e0e4-4ba5-a356-5ce55f6812ac",
   "metadata": {},
   "source": [
    "***\n",
    "#### Creating Data Loaders\n",
    "\n",
    "We'll use `ImageDataGenerator` to load in our images in batches.\n",
    "***"
   ]
  },
  {
   "cell_type": "code",
   "execution_count": 3,
   "id": "74d382b5-0c60-41fe-b80c-2bdd5209bbd1",
   "metadata": {},
   "outputs": [
    {
     "name": "stdout",
     "output_type": "stream",
     "text": [
      "Trainig images:\n",
      "ERROR! Session/line number was not unique in database. History logging moved to new session 42\n",
      "Found 750 images belonging to 10 classes.\n",
      "Testing Images:\n",
      "Found 2500 images belonging to 10 classes.\n"
     ]
    }
   ],
   "source": [
    "# Setup data inputs\n",
    "from tensorflow.keras.preprocessing.image import ImageDataGenerator\n",
    "\n",
    "IMAGE_SHAPE = (224,224)\n",
    "BATCH_SIZE = 32\n",
    "\n",
    "train_dir = \"10_food_classes_10_percent/train/\"\n",
    "test_dir = \"10_food_classes_10_percent/test/\"\n",
    "\n",
    "train_datagen = ImageDataGenerator(rescale=1/255.)\n",
    "test_datagen = ImageDataGenerator(rescale=1/255.)\n",
    "\n",
    "print(\"Trainig images:\")\n",
    "train_data_10_percent = train_datagen.flow_from_directory(train_dir,\n",
    "                                                          target_size=IMAGE_SHAPE,\n",
    "                                                         batch_size=BATCH_SIZE,\n",
    "                                                         class_mode=\"categorical\")\n",
    "\n",
    "print(\"Testing Images:\")\n",
    "test_data = test_datagen.flow_from_directory(test_dir,\n",
    "                                            target_size=IMAGE_SHAPE,\n",
    "                                            batch_size=BATCH_SIZE,\n",
    "                                            class_mode=\"categorical\")"
   ]
  },
  {
   "cell_type": "markdown",
   "id": "ed097ef8-6fa9-4995-a09e-9d76487ad062",
   "metadata": {},
   "source": [
    "#### Setting up Callbacks \n",
    "\n",
    "Things to run whilst our model trains\n",
    "Extra functionality you can add to your model to be performed during or after training. Popular callbacks:\n",
    "\n",
    "* Tracking experiments with TensorBoard callback\n",
    "* Model Checkpoints with ModelCheckpoint callback\n",
    "* Stopping a model from training too long with EarlyStopping callback"
   ]
  },
  {
   "cell_type": "code",
   "execution_count": 5,
   "id": "0cf4546a-6e34-4cb4-a47e-2eb5f729151d",
   "metadata": {},
   "outputs": [],
   "source": [
    "## Create TensorBoard Callback\n",
    "import datetime\n",
    "\n",
    "def create_tensorboard_callback(dir_name, experiment_name):\n",
    "    log_dir = dir_name + \"/\" + experiment_name + \"/\" + datetime.datetime.now().strftime(\"%Y%m%d\")\n",
    "    tensorboard_callback = tf.keras.callbacks.Tensorboard(log_dir=log_dir)\n",
    "    print(f\"Saving log files to: {log_dir}\")\n",
    "    return tensorboard_callback    "
   ]
  },
  {
   "cell_type": "markdown",
   "id": "c1e28879-e3c5-4412-a74b-92444b4bcf1f",
   "metadata": {},
   "source": [
    "#### Creating Models using TensorFlow Hub\n",
    "\n",
    "Pre-trained model at : https://tfhub.dev/"
   ]
  },
  {
   "cell_type": "code",
   "execution_count": null,
   "id": "cf65be9f-ba91-4fef-84eb-6b6951f525d0",
   "metadata": {},
   "outputs": [
    {
     "name": "stderr",
     "output_type": "stream",
     "text": [
      "ERROR:root:Internal Python error in the inspect module.\n",
      "Below is the traceback from this internal error.\n",
      "\n",
      "ERROR:root:Internal Python error in the inspect module.\n",
      "Below is the traceback from this internal error.\n",
      "\n",
      "ERROR:root:Internal Python error in the inspect module.\n",
      "Below is the traceback from this internal error.\n",
      "\n"
     ]
    },
    {
     "name": "stdout",
     "output_type": "stream",
     "text": [
      "Traceback (most recent call last):\n",
      "  File \"D:\\Softwares\\Installed\\Anaconda\\envs\\deepl\\lib\\site-packages\\IPython\\core\\interactiveshell.py\", line 3343, in run_code\n",
      "    exec(code_obj, self.user_global_ns, self.user_ns)\n",
      "  File \"<ipython-input-7-5c017171c13e>\", line 1, in <module>\n",
      "    import tensorflow_hub as hub\n",
      "ModuleNotFoundError: No module named 'tensorflow_hub'\n",
      "\n",
      "During handling of the above exception, another exception occurred:\n",
      "\n",
      "Traceback (most recent call last):\n",
      "  File \"D:\\Softwares\\Installed\\Anaconda\\envs\\deepl\\lib\\site-packages\\IPython\\core\\interactiveshell.py\", line 2044, in showtraceback\n",
      "    stb = value._render_traceback_()\n",
      "AttributeError: 'ModuleNotFoundError' object has no attribute '_render_traceback_'\n",
      "\n",
      "During handling of the above exception, another exception occurred:\n",
      "\n",
      "Traceback (most recent call last):\n",
      "  File \"D:\\Softwares\\Installed\\Anaconda\\envs\\deepl\\lib\\site-packages\\IPython\\core\\ultratb.py\", line 1169, in get_records\n",
      "    return _fixed_getinnerframes(etb, number_of_lines_of_context, tb_offset)\n",
      "  File \"D:\\Softwares\\Installed\\Anaconda\\envs\\deepl\\lib\\site-packages\\IPython\\core\\ultratb.py\", line 316, in wrapped\n",
      "    return f(*args, **kwargs)\n",
      "  File \"D:\\Softwares\\Installed\\Anaconda\\envs\\deepl\\lib\\site-packages\\IPython\\core\\ultratb.py\", line 350, in _fixed_getinnerframes\n",
      "    records = fix_frame_records_filenames(inspect.getinnerframes(etb, context))\n",
      "  File \"D:\\Softwares\\Installed\\Anaconda\\envs\\deepl\\lib\\inspect.py\", line 1490, in getinnerframes\n",
      "    frameinfo = (tb.tb_frame,) + getframeinfo(tb, context)\n",
      "  File \"D:\\Softwares\\Installed\\Anaconda\\envs\\deepl\\lib\\inspect.py\", line 1448, in getframeinfo\n",
      "    filename = getsourcefile(frame) or getfile(frame)\n",
      "  File \"D:\\Softwares\\Installed\\Anaconda\\envs\\deepl\\lib\\inspect.py\", line 696, in getsourcefile\n",
      "    if getattr(getmodule(object, filename), '__loader__', None) is not None:\n",
      "  File \"D:\\Softwares\\Installed\\Anaconda\\envs\\deepl\\lib\\inspect.py\", line 733, in getmodule\n",
      "    if ismodule(module) and hasattr(module, '__file__'):\n",
      "  File \"D:\\Softwares\\Installed\\Anaconda\\envs\\deepl\\lib\\site-packages\\tensorflow\\__init__.py\", line 50, in __getattr__\n",
      "    module = self._load()\n",
      "  File \"D:\\Softwares\\Installed\\Anaconda\\envs\\deepl\\lib\\site-packages\\tensorflow\\__init__.py\", line 44, in _load\n",
      "    module = _importlib.import_module(self.__name__)\n",
      "  File \"D:\\Softwares\\Installed\\Anaconda\\envs\\deepl\\lib\\importlib\\__init__.py\", line 126, in import_module\n",
      "    return _bootstrap._gcd_import(name[level:], package, level)\n",
      "  File \"<frozen importlib._bootstrap>\", line 994, in _gcd_import\n",
      "  File \"<frozen importlib._bootstrap>\", line 971, in _find_and_load\n",
      "  File \"<frozen importlib._bootstrap>\", line 953, in _find_and_load_unlocked\n",
      "ModuleNotFoundError: No module named 'tensorflow_core.estimator'\n",
      "Traceback (most recent call last):\n",
      "  File \"D:\\Softwares\\Installed\\Anaconda\\envs\\deepl\\lib\\site-packages\\IPython\\core\\interactiveshell.py\", line 3343, in run_code\n",
      "    exec(code_obj, self.user_global_ns, self.user_ns)\n",
      "  File \"<ipython-input-7-5c017171c13e>\", line 1, in <module>\n",
      "    import tensorflow_hub as hub\n",
      "ModuleNotFoundError: No module named 'tensorflow_hub'\n",
      "\n",
      "During handling of the above exception, another exception occurred:\n",
      "\n",
      "Traceback (most recent call last):\n",
      "  File \"D:\\Softwares\\Installed\\Anaconda\\envs\\deepl\\lib\\site-packages\\IPython\\core\\interactiveshell.py\", line 2044, in showtraceback\n",
      "    stb = value._render_traceback_()\n",
      "AttributeError: 'ModuleNotFoundError' object has no attribute '_render_traceback_'\n",
      "\n",
      "During handling of the above exception, another exception occurred:\n",
      "\n",
      "Traceback (most recent call last):\n",
      "  File \"D:\\Softwares\\Installed\\Anaconda\\envs\\deepl\\lib\\site-packages\\IPython\\core\\interactiveshell.py\", line 3263, in run_ast_nodes\n",
      "    if (await self.run_code(code, result,  async_=asy)):\n",
      "  File \"D:\\Softwares\\Installed\\Anaconda\\envs\\deepl\\lib\\site-packages\\IPython\\core\\interactiveshell.py\", line 3360, in run_code\n",
      "    self.showtraceback(running_compiled_code=True)\n",
      "  File \"D:\\Softwares\\Installed\\Anaconda\\envs\\deepl\\lib\\site-packages\\IPython\\core\\interactiveshell.py\", line 2047, in showtraceback\n",
      "    value, tb, tb_offset=tb_offset)\n",
      "  File \"D:\\Softwares\\Installed\\Anaconda\\envs\\deepl\\lib\\site-packages\\IPython\\core\\ultratb.py\", line 1436, in structured_traceback\n",
      "    self, etype, value, tb, tb_offset, number_of_lines_of_context)\n",
      "  File \"D:\\Softwares\\Installed\\Anaconda\\envs\\deepl\\lib\\site-packages\\IPython\\core\\ultratb.py\", line 1336, in structured_traceback\n",
      "    self, etype, value, tb, tb_offset, number_of_lines_of_context\n",
      "  File \"D:\\Softwares\\Installed\\Anaconda\\envs\\deepl\\lib\\site-packages\\IPython\\core\\ultratb.py\", line 1193, in structured_traceback\n",
      "    tb_offset)\n",
      "  File \"D:\\Softwares\\Installed\\Anaconda\\envs\\deepl\\lib\\site-packages\\IPython\\core\\ultratb.py\", line 1150, in format_exception_as_a_whole\n",
      "    last_unique, recursion_repeat = find_recursion(orig_etype, evalue, records)\n",
      "  File \"D:\\Softwares\\Installed\\Anaconda\\envs\\deepl\\lib\\site-packages\\IPython\\core\\ultratb.py\", line 451, in find_recursion\n",
      "    return len(records), 0\n",
      "TypeError: object of type 'NoneType' has no len()\n",
      "\n",
      "During handling of the above exception, another exception occurred:\n",
      "\n",
      "Traceback (most recent call last):\n",
      "  File \"D:\\Softwares\\Installed\\Anaconda\\envs\\deepl\\lib\\site-packages\\IPython\\core\\interactiveshell.py\", line 2044, in showtraceback\n",
      "    stb = value._render_traceback_()\n",
      "AttributeError: 'TypeError' object has no attribute '_render_traceback_'\n",
      "\n",
      "During handling of the above exception, another exception occurred:\n",
      "\n",
      "Traceback (most recent call last):\n",
      "  File \"D:\\Softwares\\Installed\\Anaconda\\envs\\deepl\\lib\\site-packages\\IPython\\core\\ultratb.py\", line 1169, in get_records\n",
      "    return _fixed_getinnerframes(etb, number_of_lines_of_context, tb_offset)\n",
      "  File \"D:\\Softwares\\Installed\\Anaconda\\envs\\deepl\\lib\\site-packages\\IPython\\core\\ultratb.py\", line 316, in wrapped\n",
      "    return f(*args, **kwargs)\n",
      "  File \"D:\\Softwares\\Installed\\Anaconda\\envs\\deepl\\lib\\site-packages\\IPython\\core\\ultratb.py\", line 350, in _fixed_getinnerframes\n",
      "    records = fix_frame_records_filenames(inspect.getinnerframes(etb, context))\n",
      "  File \"D:\\Softwares\\Installed\\Anaconda\\envs\\deepl\\lib\\inspect.py\", line 1490, in getinnerframes\n",
      "    frameinfo = (tb.tb_frame,) + getframeinfo(tb, context)\n",
      "  File \"D:\\Softwares\\Installed\\Anaconda\\envs\\deepl\\lib\\inspect.py\", line 1448, in getframeinfo\n",
      "    filename = getsourcefile(frame) or getfile(frame)\n",
      "  File \"D:\\Softwares\\Installed\\Anaconda\\envs\\deepl\\lib\\inspect.py\", line 696, in getsourcefile\n",
      "    if getattr(getmodule(object, filename), '__loader__', None) is not None:\n",
      "  File \"D:\\Softwares\\Installed\\Anaconda\\envs\\deepl\\lib\\inspect.py\", line 733, in getmodule\n",
      "    if ismodule(module) and hasattr(module, '__file__'):\n",
      "  File \"D:\\Softwares\\Installed\\Anaconda\\envs\\deepl\\lib\\site-packages\\tensorflow\\__init__.py\", line 50, in __getattr__\n",
      "    module = self._load()\n",
      "  File \"D:\\Softwares\\Installed\\Anaconda\\envs\\deepl\\lib\\site-packages\\tensorflow\\__init__.py\", line 44, in _load\n",
      "    module = _importlib.import_module(self.__name__)\n",
      "  File \"D:\\Softwares\\Installed\\Anaconda\\envs\\deepl\\lib\\importlib\\__init__.py\", line 126, in import_module\n",
      "    return _bootstrap._gcd_import(name[level:], package, level)\n",
      "  File \"<frozen importlib._bootstrap>\", line 994, in _gcd_import\n",
      "  File \"<frozen importlib._bootstrap>\", line 971, in _find_and_load\n",
      "  File \"<frozen importlib._bootstrap>\", line 953, in _find_and_load_unlocked\n",
      "ModuleNotFoundError: No module named 'tensorflow_core.estimator'\n",
      "Traceback (most recent call last):\n",
      "  File \"D:\\Softwares\\Installed\\Anaconda\\envs\\deepl\\lib\\site-packages\\IPython\\core\\interactiveshell.py\", line 3343, in run_code\n",
      "    exec(code_obj, self.user_global_ns, self.user_ns)\n",
      "  File \"<ipython-input-7-5c017171c13e>\", line 1, in <module>\n",
      "    import tensorflow_hub as hub\n",
      "ModuleNotFoundError: No module named 'tensorflow_hub'\n",
      "\n",
      "During handling of the above exception, another exception occurred:\n",
      "\n",
      "Traceback (most recent call last):\n",
      "  File \"D:\\Softwares\\Installed\\Anaconda\\envs\\deepl\\lib\\site-packages\\IPython\\core\\interactiveshell.py\", line 2044, in showtraceback\n",
      "    stb = value._render_traceback_()\n",
      "AttributeError: 'ModuleNotFoundError' object has no attribute '_render_traceback_'\n",
      "\n",
      "During handling of the above exception, another exception occurred:\n",
      "\n",
      "Traceback (most recent call last):\n",
      "  File \"D:\\Softwares\\Installed\\Anaconda\\envs\\deepl\\lib\\site-packages\\IPython\\core\\interactiveshell.py\", line 3263, in run_ast_nodes\n",
      "    if (await self.run_code(code, result,  async_=asy)):\n",
      "  File \"D:\\Softwares\\Installed\\Anaconda\\envs\\deepl\\lib\\site-packages\\IPython\\core\\interactiveshell.py\", line 3360, in run_code\n",
      "    self.showtraceback(running_compiled_code=True)\n",
      "  File \"D:\\Softwares\\Installed\\Anaconda\\envs\\deepl\\lib\\site-packages\\IPython\\core\\interactiveshell.py\", line 2047, in showtraceback\n",
      "    value, tb, tb_offset=tb_offset)\n",
      "  File \"D:\\Softwares\\Installed\\Anaconda\\envs\\deepl\\lib\\site-packages\\IPython\\core\\ultratb.py\", line 1436, in structured_traceback\n",
      "    self, etype, value, tb, tb_offset, number_of_lines_of_context)\n",
      "  File \"D:\\Softwares\\Installed\\Anaconda\\envs\\deepl\\lib\\site-packages\\IPython\\core\\ultratb.py\", line 1336, in structured_traceback\n",
      "    self, etype, value, tb, tb_offset, number_of_lines_of_context\n",
      "  File \"D:\\Softwares\\Installed\\Anaconda\\envs\\deepl\\lib\\site-packages\\IPython\\core\\ultratb.py\", line 1193, in structured_traceback\n",
      "    tb_offset)\n",
      "  File \"D:\\Softwares\\Installed\\Anaconda\\envs\\deepl\\lib\\site-packages\\IPython\\core\\ultratb.py\", line 1150, in format_exception_as_a_whole\n",
      "    last_unique, recursion_repeat = find_recursion(orig_etype, evalue, records)\n",
      "  File \"D:\\Softwares\\Installed\\Anaconda\\envs\\deepl\\lib\\site-packages\\IPython\\core\\ultratb.py\", line 451, in find_recursion\n",
      "    return len(records), 0\n",
      "TypeError: object of type 'NoneType' has no len()\n",
      "\n",
      "During handling of the above exception, another exception occurred:\n",
      "\n",
      "Traceback (most recent call last):\n",
      "  File \"D:\\Softwares\\Installed\\Anaconda\\envs\\deepl\\lib\\site-packages\\IPython\\core\\interactiveshell.py\", line 2044, in showtraceback\n",
      "    stb = value._render_traceback_()\n",
      "AttributeError: 'TypeError' object has no attribute '_render_traceback_'\n",
      "\n",
      "During handling of the above exception, another exception occurred:\n",
      "\n",
      "Traceback (most recent call last):\n",
      "  File \"D:\\Softwares\\Installed\\Anaconda\\envs\\deepl\\lib\\site-packages\\IPython\\core\\interactiveshell.py\", line 2895, in _run_cell\n",
      "    return runner(coro)\n",
      "  File \"D:\\Softwares\\Installed\\Anaconda\\envs\\deepl\\lib\\site-packages\\IPython\\core\\async_helpers.py\", line 68, in _pseudo_sync_runner\n",
      "    coro.send(None)\n",
      "  File \"D:\\Softwares\\Installed\\Anaconda\\envs\\deepl\\lib\\site-packages\\IPython\\core\\interactiveshell.py\", line 3072, in run_cell_async\n",
      "    interactivity=interactivity, compiler=compiler, result=result)\n",
      "  File \"D:\\Softwares\\Installed\\Anaconda\\envs\\deepl\\lib\\site-packages\\IPython\\core\\interactiveshell.py\", line 3282, in run_ast_nodes\n",
      "    self.showtraceback()\n",
      "  File \"D:\\Softwares\\Installed\\Anaconda\\envs\\deepl\\lib\\site-packages\\IPython\\core\\interactiveshell.py\", line 2047, in showtraceback\n",
      "    value, tb, tb_offset=tb_offset)\n",
      "  File \"D:\\Softwares\\Installed\\Anaconda\\envs\\deepl\\lib\\site-packages\\IPython\\core\\ultratb.py\", line 1436, in structured_traceback\n",
      "    self, etype, value, tb, tb_offset, number_of_lines_of_context)\n",
      "  File \"D:\\Softwares\\Installed\\Anaconda\\envs\\deepl\\lib\\site-packages\\IPython\\core\\ultratb.py\", line 1336, in structured_traceback\n",
      "    self, etype, value, tb, tb_offset, number_of_lines_of_context\n",
      "  File \"D:\\Softwares\\Installed\\Anaconda\\envs\\deepl\\lib\\site-packages\\IPython\\core\\ultratb.py\", line 1211, in structured_traceback\n",
      "    chained_exceptions_tb_offset)\n",
      "  File \"D:\\Softwares\\Installed\\Anaconda\\envs\\deepl\\lib\\site-packages\\IPython\\core\\ultratb.py\", line 1150, in format_exception_as_a_whole\n",
      "    last_unique, recursion_repeat = find_recursion(orig_etype, evalue, records)\n",
      "  File \"D:\\Softwares\\Installed\\Anaconda\\envs\\deepl\\lib\\site-packages\\IPython\\core\\ultratb.py\", line 451, in find_recursion\n",
      "    return len(records), 0\n",
      "TypeError: object of type 'NoneType' has no len()\n",
      "\n",
      "During handling of the above exception, another exception occurred:\n",
      "\n",
      "Traceback (most recent call last):\n",
      "  File \"D:\\Softwares\\Installed\\Anaconda\\envs\\deepl\\lib\\site-packages\\IPython\\core\\interactiveshell.py\", line 2044, in showtraceback\n",
      "    stb = value._render_traceback_()\n",
      "AttributeError: 'TypeError' object has no attribute '_render_traceback_'\n",
      "\n",
      "During handling of the above exception, another exception occurred:\n",
      "\n",
      "Traceback (most recent call last):\n",
      "  File \"D:\\Softwares\\Installed\\Anaconda\\envs\\deepl\\lib\\site-packages\\IPython\\core\\ultratb.py\", line 1169, in get_records\n",
      "    return _fixed_getinnerframes(etb, number_of_lines_of_context, tb_offset)\n",
      "  File \"D:\\Softwares\\Installed\\Anaconda\\envs\\deepl\\lib\\site-packages\\IPython\\core\\ultratb.py\", line 316, in wrapped\n",
      "    return f(*args, **kwargs)\n",
      "  File \"D:\\Softwares\\Installed\\Anaconda\\envs\\deepl\\lib\\site-packages\\IPython\\core\\ultratb.py\", line 350, in _fixed_getinnerframes\n",
      "    records = fix_frame_records_filenames(inspect.getinnerframes(etb, context))\n",
      "  File \"D:\\Softwares\\Installed\\Anaconda\\envs\\deepl\\lib\\inspect.py\", line 1490, in getinnerframes\n",
      "    frameinfo = (tb.tb_frame,) + getframeinfo(tb, context)\n",
      "  File \"D:\\Softwares\\Installed\\Anaconda\\envs\\deepl\\lib\\inspect.py\", line 1448, in getframeinfo\n",
      "    filename = getsourcefile(frame) or getfile(frame)\n",
      "  File \"D:\\Softwares\\Installed\\Anaconda\\envs\\deepl\\lib\\inspect.py\", line 696, in getsourcefile\n",
      "    if getattr(getmodule(object, filename), '__loader__', None) is not None:\n",
      "  File \"D:\\Softwares\\Installed\\Anaconda\\envs\\deepl\\lib\\inspect.py\", line 733, in getmodule\n",
      "    if ismodule(module) and hasattr(module, '__file__'):\n",
      "  File \"D:\\Softwares\\Installed\\Anaconda\\envs\\deepl\\lib\\site-packages\\tensorflow\\__init__.py\", line 50, in __getattr__\n",
      "    module = self._load()\n",
      "  File \"D:\\Softwares\\Installed\\Anaconda\\envs\\deepl\\lib\\site-packages\\tensorflow\\__init__.py\", line 44, in _load\n",
      "    module = _importlib.import_module(self.__name__)\n",
      "  File \"D:\\Softwares\\Installed\\Anaconda\\envs\\deepl\\lib\\importlib\\__init__.py\", line 126, in import_module\n",
      "    return _bootstrap._gcd_import(name[level:], package, level)\n",
      "  File \"<frozen importlib._bootstrap>\", line 994, in _gcd_import\n",
      "  File \"<frozen importlib._bootstrap>\", line 971, in _find_and_load\n",
      "  File \"<frozen importlib._bootstrap>\", line 953, in _find_and_load_unlocked\n",
      "ModuleNotFoundError: No module named 'tensorflow_core.estimator'\n"
     ]
    }
   ],
   "source": [
    "import tensorflow_hub as hub"
   ]
  },
  {
   "cell_type": "code",
   "execution_count": null,
   "id": "5aca2b73-c37e-4f10-89a9-81fa3d5a4a1a",
   "metadata": {},
   "outputs": [],
   "source": []
  }
 ],
 "metadata": {
  "kernelspec": {
   "display_name": "Python 3",
   "language": "python",
   "name": "python3"
  },
  "language_info": {
   "codemirror_mode": {
    "name": "ipython",
    "version": 3
   },
   "file_extension": ".py",
   "mimetype": "text/x-python",
   "name": "python",
   "nbconvert_exporter": "python",
   "pygments_lexer": "ipython3",
   "version": "3.6.13"
  }
 },
 "nbformat": 4,
 "nbformat_minor": 5
}
